Traceback (most recent call last):
  File "/Volumes/workplace/personal/pyhab/.venv/lib/python3.9/site-packages/jupyter_cache/executors/utils.py", line 51, in single_nb_execution
    executenb(
  File "/Volumes/workplace/personal/pyhab/.venv/lib/python3.9/site-packages/nbclient/client.py", line 1112, in execute
    return NotebookClient(nb=nb, resources=resources, km=km, **kwargs).execute()
  File "/Volumes/workplace/personal/pyhab/.venv/lib/python3.9/site-packages/nbclient/util.py", line 74, in wrapped
    return just_run(coro(*args, **kwargs))
  File "/Volumes/workplace/personal/pyhab/.venv/lib/python3.9/site-packages/nbclient/util.py", line 53, in just_run
    return loop.run_until_complete(coro)
  File "/Users/jwwalker/.pyenv/versions/3.9.1/lib/python3.9/asyncio/base_events.py", line 642, in run_until_complete
    return future.result()
  File "/Volumes/workplace/personal/pyhab/.venv/lib/python3.9/site-packages/nbclient/client.py", line 553, in async_execute
    await self.async_execute_cell(
  File "/Volumes/workplace/personal/pyhab/.venv/lib/python3.9/site-packages/nbclient/client.py", line 857, in async_execute_cell
    self._check_raise_for_error(cell, exec_reply)
  File "/Volumes/workplace/personal/pyhab/.venv/lib/python3.9/site-packages/nbclient/client.py", line 760, in _check_raise_for_error
    raise CellExecutionError.from_cell_and_msg(cell, exec_reply_content)
nbclient.exceptions.CellExecutionError: An error occurred while executing the following cell:
------------------
# Density is defined as mass / volume:
# rho = m / V
_.solve(P).subs(m/V, rho)
------------------

[0;31m---------------------------------------------------------------------------[0m
[0;31mAttributeError[0m                            Traceback (most recent call last)
[0;32m/var/folders/gw/fwbnxl652jx80ff49ndt1x6jzjvjfq/T/ipykernel_34288/460363906.py[0m in [0;36m<module>[0;34m[0m
[1;32m      1[0m [0;31m# Density is defined as mass / volume:[0m[0;34m[0m[0;34m[0m[0;34m[0m[0m
[1;32m      2[0m [0;31m# rho = m / V[0m[0;34m[0m[0;34m[0m[0;34m[0m[0m
[0;32m----> 3[0;31m [0m_[0m[0;34m.[0m[0msolve[0m[0;34m([0m[0mP[0m[0;34m)[0m[0;34m.[0m[0msubs[0m[0;34m([0m[0mm[0m[0;34m/[0m[0mV[0m[0;34m,[0m [0mrho[0m[0;34m)[0m[0;34m[0m[0;34m[0m[0m
[0m
[0;31mAttributeError[0m: 'list' object has no attribute 'subs'
AttributeError: 'list' object has no attribute 'subs'

